Traceback (most recent call last):
  File "/gscratch/ark/devinl6/envs/align/lib/python3.10/site-packages/urllib3/connection.py", line 198, in _new_conn
    sock = connection.create_connection(
  File "/gscratch/ark/devinl6/envs/align/lib/python3.10/site-packages/urllib3/util/connection.py", line 60, in create_connection
    for res in socket.getaddrinfo(host, port, family, socket.SOCK_STREAM):
  File "/gscratch/ark/devinl6/envs/align/lib/python3.10/socket.py", line 967, in getaddrinfo
    for res in _socket.getaddrinfo(host, port, family, type, proto, flags):
socket.gaierror: [Errno -2] Name or service not known

The above exception was the direct cause of the following exception:

Traceback (most recent call last):
  File "/gscratch/ark/devinl6/envs/align/lib/python3.10/site-packages/urllib3/connectionpool.py", line 787, in urlopen
    response = self._make_request(
  File "/gscratch/ark/devinl6/envs/align/lib/python3.10/site-packages/urllib3/connectionpool.py", line 488, in _make_request
    raise new_e
  File "/gscratch/ark/devinl6/envs/align/lib/python3.10/site-packages/urllib3/connectionpool.py", line 464, in _make_request
    self._validate_conn(conn)
  File "/gscratch/ark/devinl6/envs/align/lib/python3.10/site-packages/urllib3/connectionpool.py", line 1093, in _validate_conn
    conn.connect()
  File "/gscratch/ark/devinl6/envs/align/lib/python3.10/site-packages/urllib3/connection.py", line 753, in connect
    self.sock = sock = self._new_conn()
  File "/gscratch/ark/devinl6/envs/align/lib/python3.10/site-packages/urllib3/connection.py", line 205, in _new_conn
    raise NameResolutionError(self.host, self, e) from e
urllib3.exceptions.NameResolutionError: <urllib3.connection.HTTPSConnection object at 0x147f937312d0>: Failed to resolve 'huggingface.co' ([Errno -2] Name or service not known)

The above exception was the direct cause of the following exception:

Traceback (most recent call last):
  File "/gscratch/ark/devinl6/envs/align/lib/python3.10/site-packages/requests/adapters.py", line 667, in send
    resp = conn.urlopen(
  File "/gscratch/ark/devinl6/envs/align/lib/python3.10/site-packages/urllib3/connectionpool.py", line 841, in urlopen
    retries = retries.increment(
  File "/gscratch/ark/devinl6/envs/align/lib/python3.10/site-packages/urllib3/util/retry.py", line 519, in increment
    raise MaxRetryError(_pool, url, reason) from reason  # type: ignore[arg-type]
urllib3.exceptions.MaxRetryError: HTTPSConnectionPool(host='huggingface.co', port=443): Max retries exceeded with url: /api/models/meta-llama/Llama-3.2-1B-Instruct/tree/main/additional_chat_templates?recursive=False&expand=False (Caused by NameResolutionError("<urllib3.connection.HTTPSConnection object at 0x147f937312d0>: Failed to resolve 'huggingface.co' ([Errno -2] Name or service not known)"))

During handling of the above exception, another exception occurred:

Traceback (most recent call last):
  File "/mmfs1/gscratch/ark/devinl6/preference/preference-decoding/utils/eval_approx.py", line 47, in <module>
    tokenizer = AutoTokenizer.from_pretrained(base_model_path)
  File "/gscratch/ark/devinl6/envs/align/lib/python3.10/site-packages/transformers/models/auto/tokenization_auto.py", line 1013, in from_pretrained
    return tokenizer_class.from_pretrained(pretrained_model_name_or_path, *inputs, **kwargs)
  File "/gscratch/ark/devinl6/envs/align/lib/python3.10/site-packages/transformers/tokenization_utils_base.py", line 1968, in from_pretrained
    for template in list_repo_templates(
  File "/gscratch/ark/devinl6/envs/align/lib/python3.10/site-packages/transformers/utils/hub.py", line 161, in list_repo_templates
    return [
  File "/gscratch/ark/devinl6/envs/align/lib/python3.10/site-packages/transformers/utils/hub.py", line 161, in <listcomp>
    return [
  File "/gscratch/ark/devinl6/envs/align/lib/python3.10/site-packages/huggingface_hub/hf_api.py", line 3168, in list_repo_tree
    for path_info in paginate(path=tree_url, headers=headers, params={"recursive": recursive, "expand": expand}):
  File "/gscratch/ark/devinl6/envs/align/lib/python3.10/site-packages/huggingface_hub/utils/_pagination.py", line 36, in paginate
    r = session.get(path, params=params, headers=headers)
  File "/gscratch/ark/devinl6/envs/align/lib/python3.10/site-packages/requests/sessions.py", line 602, in get
    return self.request("GET", url, **kwargs)
  File "/gscratch/ark/devinl6/envs/align/lib/python3.10/site-packages/requests/sessions.py", line 589, in request
    resp = self.send(prep, **send_kwargs)
  File "/gscratch/ark/devinl6/envs/align/lib/python3.10/site-packages/requests/sessions.py", line 703, in send
    r = adapter.send(request, **kwargs)
  File "/gscratch/ark/devinl6/envs/align/lib/python3.10/site-packages/huggingface_hub/utils/_http.py", line 96, in send
    return super().send(request, *args, **kwargs)
  File "/gscratch/ark/devinl6/envs/align/lib/python3.10/site-packages/requests/adapters.py", line 700, in send
    raise ConnectionError(e, request=request)
requests.exceptions.ConnectionError: (MaxRetryError('HTTPSConnectionPool(host=\'huggingface.co\', port=443): Max retries exceeded with url: /api/models/meta-llama/Llama-3.2-1B-Instruct/tree/main/additional_chat_templates?recursive=False&expand=False (Caused by NameResolutionError("<urllib3.connection.HTTPSConnection object at 0x147f937312d0>: Failed to resolve \'huggingface.co\' ([Errno -2] Name or service not known)"))'), '(Request ID: 9b0e1edc-4142-48df-8ad2-01d561f0181b)')
